<?xml version="1.0" ?>
<!-- =================================================================================== -->
<!-- |    This document was autogenerated by xacro from ./car.urdf.xacro               | -->
<!-- |    EDITING THIS FILE BY HAND IS NOT RECOMMENDED                                 | -->
<!-- =================================================================================== -->
<robot name="car">
  <material name="gray">
    <color rgba="0.8 0.8 0.8 1"/>
  </material>
  <link name="base">
    <visual>
      <origin rpy="0.0 0.0 0.0" xyz="0.0 0.0 0.0"/>
      <geometry>
        <box size="5 2 0.1"/>
      </geometry>
      <material name="gray"/>
    </visual>
    <inertial>
      <origin rpy="0.0 0.0 0.0" xyz="0.0 0.0 0.0"/>
      <mass value="100.0"/>
      <inertia ixx="1.0" ixy="0.0" ixz="0.0" iyy="1.0" iyz="0.0" izz="1.0"/>
    </inertial>
    <collision>
      <origin rpy="0.0 0.0 0.0" xyz="0.0 0.0 0.0"/>
      <geometry>
        <box size="5 2 0.1"/>
      </geometry>
    </collision>
  </link>
  <link name="turn_left_turn">
        </link>
  <joint name="joint_left_turn" type="prismatic">
    <origin rpy="0 0 0" xyz="-2 -1.025 0"/>
    <parent link="base"/>
    <child link="turn_left_turn"/>
    <axis xyz="0.0 0.0 1"/>
    <limit effort="1.0" lower="-3.1415926" upper="3.1415926" velocity="1.0"/>
  </joint>
  <link name="wheel_left_bottom">
    <inertial>
      <origin rpy="0.0 0.0 0.0" xyz="0.0 0.0 0.0"/>
      <mass value="10.0"/>
      <inertia ixx="1.0" ixy="0.0" ixz="0.0" iyy="1.0" iyz="0.0" izz="1.0"/>
    </inertial>
    <visual>
      <origin rpy="0.0 0.0 0.0" xyz="0.0 -0.025 0"/>
      <geometry>
        <mesh filename="package://car_description/meshes/Wheel.dae" scale="7 7 7"/>
      </geometry>
    </visual>
    <collision>
      <origin rpy="1.5707963  0.0 0.0" xyz="0.0 0.0 0.0"/>
      <geometry>
        <cylinder length="0.05" radius="0.25"/>
      </geometry>
      <surface>
        <friction>
          <ode>
            <mu>1000000.0</mu>
            <mu2>1000000.0</mu2>
            <slip1>1.0</slip1>
            <slip2>1.0</slip2>
          </ode>
        </friction>
      </surface>
    </collision>
  </link>
  <joint name="joint_left_bottom" type="continuous">
    <origin rpy="0 0 0" xyz="0 0 0"/>
    <parent link="turn_left_turn"/>
    <child link="wheel_left_bottom"/>
    <axis xyz="0.0 1 0.0"/>
    <dynamics damping="0.7" friction="1000"/>
  </joint>
  <link name="turn_right_turn">
        </link>
  <joint name="joint_right_turn" type="prismatic">
    <origin rpy="0 0 0" xyz="-2 1.025 0"/>
    <parent link="base"/>
    <child link="turn_right_turn"/>
    <axis xyz="0.0 0.0 1"/>
    <limit effort="1.0" lower="-3.1415926" upper="3.1415926" velocity="1.0"/>
  </joint>
  <link name="wheel_left_top">
    <inertial>
      <origin rpy="0.0 0.0 0.0" xyz="0.0 0.0 0.0"/>
      <mass value="10.0"/>
      <inertia ixx="1.0" ixy="0.0" ixz="0.0" iyy="1.0" iyz="0.0" izz="1.0"/>
    </inertial>
    <visual>
      <origin rpy="0.0 0.0 0.0" xyz="0.0 -0.025 0"/>
      <geometry>
        <mesh filename="package://car_description/meshes/Wheel.dae" scale="7 7 7"/>
      </geometry>
    </visual>
    <collision>
      <origin rpy="1.5707963  0.0 0.0" xyz="0.0 0.0 0.0"/>
      <geometry>
        <cylinder length="0.05" radius="0.25"/>
      </geometry>
      <surface>
        <friction>
          <ode>
            <mu>1000000.0</mu>
            <mu2>1000000.0</mu2>
            <slip1>1.0</slip1>
            <slip2>1.0</slip2>
          </ode>
        </friction>
      </surface>
    </collision>
  </link>
  <joint name="joint_left_top" type="continuous">
    <origin rpy="0 0 0" xyz="0 0 0"/>
    <parent link="turn_right_turn"/>
    <child link="wheel_left_top"/>
    <axis xyz="0.0 1 0.0"/>
    <dynamics damping="0.7" friction="1000"/>
  </joint>
  <link name="wheel_right_bottom">
    <inertial>
      <origin rpy="0.0 0.0 0.0" xyz="0.0 0.0 0.0"/>
      <mass value="10.0"/>
      <inertia ixx="1.0" ixy="0.0" ixz="0.0" iyy="1.0" iyz="0.0" izz="1.0"/>
    </inertial>
    <visual>
      <origin rpy="3.1415926 0.0 0.0" xyz="0.0 0.025 0"/>
      <geometry>
        <mesh filename="package://car_description/meshes/Wheel.dae" scale="7 7 7"/>
      </geometry>
    </visual>
    <collision>
      <origin rpy="1.5707963  0.0 0.0" xyz="0.0 0.0 0.0"/>
      <geometry>
        <cylinder length="0.05" radius="0.25"/>
      </geometry>
      <surface>
        <friction>
          <ode>
            <mu>1000000.0</mu>
            <mu2>1000000.0</mu2>
            <slip1>1.0</slip1>
            <slip2>1.0</slip2>
          </ode>
        </friction>
      </surface>
    </collision>
  </link>
  <joint name="joint_right_bottom" type="continuous">
    <origin rpy="0 0 0" xyz="2 -1.025 0"/>
    <parent link="base"/>
    <child link="wheel_right_bottom"/>
    <axis xyz="0.0 1 0.0"/>
    <dynamics damping="0.7" friction="1000"/>
  </joint>
  <link name="wheel_right_top">
    <inertial>
      <origin rpy="0.0 0.0 0.0" xyz="0.0 0.0 0.0"/>
      <mass value="10.0"/>
      <inertia ixx="1.0" ixy="0.0" ixz="0.0" iyy="1.0" iyz="0.0" izz="1.0"/>
    </inertial>
    <visual>
      <origin rpy="0.0 0.0 0.0" xyz="0.0 -0.025 0"/>
      <geometry>
        <mesh filename="package://car_description/meshes/Wheel.dae" scale="7 7 7"/>
      </geometry>
    </visual>
    <collision>
      <origin rpy="1.5707963  0.0 0.0" xyz="0.0 0.0 0.0"/>
      <geometry>
        <cylinder length="0.05" radius="0.25"/>
      </geometry>
      <surface>
        <friction>
          <ode>
            <mu>1000000.0</mu>
            <mu2>1000000.0</mu2>
            <slip1>1.0</slip1>
            <slip2>1.0</slip2>
          </ode>
        </friction>
      </surface>
    </collision>
  </link>
  <joint name="joint_right_top" type="continuous">
    <origin rpy="0 0 0" xyz="2 1.025 0"/>
    <parent link="base"/>
    <child link="wheel_right_top"/>
    <axis xyz="0.0 1 0.0"/>
    <dynamics damping="0.7" friction="1000"/>
  </joint>
  <ros2_control name="IgnitionSystem" type="system">
    <hardware>
      <plugin>ign_ros2_control/IgnitionSystem</plugin>
    </hardware>
    <joint name="joint_left_bottom">
      <command_interface name="velocity">
        <param name="min">-5</param>
        <param name="max">5</param>
      </command_interface>
      <state_interface name="position"/>
      <state_interface name="velocity"/>
      <state_interface name="effort"/>
    </joint>
    <joint name="joint_left_top">
      <command_interface name="velocity">
        <param name="min">-5</param>
        <param name="max">5</param>
      </command_interface>
      <state_interface name="position"/>
      <state_interface name="velocity"/>
      <state_interface name="effort"/>
    </joint>
    <joint name="joint_right_bottom">
      <command_interface name="velocity">
        <param name="min">-5</param>
        <param name="max">5</param>
      </command_interface>
      <state_interface name="position"/>
      <state_interface name="velocity"/>
      <state_interface name="effort"/>
    </joint>
    <joint name="joint_right_top">
      <command_interface name="velocity">
        <param name="min">-5</param>
        <param name="max">5</param>
      </command_interface>
      <state_interface name="position"/>
      <state_interface name="velocity"/>
      <state_interface name="effort"/>
    </joint>
    <joint name="joint_left_turn">
      <command_interface name="position">
        <param name="min">-3.1415926</param>
        <param name="max">3.1415926</param>
      </command_interface>
      <state_interface name="position"/>
      <state_interface name="velocity"/>
      <state_interface name="effort"/>
    </joint>
    <joint name="joint_right_turn">
      <command_interface name="position">
        <param name="min">-3.1415926</param>
        <param name="max">3.1415926</param>
      </command_interface>
      <state_interface name="position"/>
      <state_interface name="velocity"/>
      <state_interface name="effort"/>
    </joint>
  </ros2_control>
  <gazebo>
    <!-- Joint state publisher -->
    <plugin filename="ign_ros2_control-system" name="ign_ros2_control::IgnitionROS2ControlPlugin">
      <parameters>/home/luqk/ros2/sim_car/install/car_description/share/car_description/config/car.yaml</parameters>
    </plugin>
  </gazebo>
</robot>
